<?xml version="1.0" ?>
<!-- =================================================================================== -->
<!-- |    This document was autogenerated by xacro from robot.urdf.xacro               | -->
<!-- |    EDITING THIS FILE BY HAND IS NOT RECOMMENDED                                 | -->
<!-- =================================================================================== -->
<robot name="robot">
  <material name="white">
    <color rgba="1 1 1 1"/>
  </material>
  <material name="orange">
    <color rgba="1 0.3 0.1 1"/>
  </material>
  <material name="blue">
    <color rgba="0.2 0.2 1 1"/>
  </material>
  <material name="black">
    <color rgba="0 0 0 1"/>
  </material>
  <material name="red">
    <color rgba="1 0 0 1"/>
  </material>
  <material name="green">
    <color rgba="0 1 0 1"/>
  </material>
  <!-- Specify some standard inertial calculations https://en.wikipedia.org/wiki/List_of_moments_of_inertia -->
  <!-- These make use of xacro's mathematical functionality -->
  <!-- BASE LINK -->
  <link name="base_link">

    </link>
  <joint name="base_footprint_joint" type="fixed">
    <parent link="base_link"/>
    <child link="base_footprint"/>
    <origin rpy="0 0 0" xyz="0 0 0"/>
  </joint>
  <link name="base_footprint">

    </link>
  <!-- CHASSIS LINK -->
  <joint name="chassis_joint" type="fixed">
    <parent link="base_link"/>
    <child link="chassis_link"/>
    <origin xyz="-0.1 0 0"/>
  </joint>
  <link name="chassis_link">
    <visual>
      <origin xyz="0.15 0 0.075"/>
      <geometry>
        <box size="0.3 0.3 0.15"/>
      </geometry>
      <material name="white"/>
    </visual>
    <collision>
      <origin xyz="0.15 0 0.075"/>
      <geometry>
        <box size="0.3 0.3 0.15"/>
      </geometry>
    </collision>
    <inertial>
      <origin rpy="0 0 0" xyz="0.15 0 0.075"/>
      <mass value="1.5"/>
      <inertia ixx="0.014062499999999999" ixy="0.0" ixz="0.0" iyy="0.014062499999999999" iyz="0.0" izz="0.0225"/>
    </inertial>
  </link>
  <gazebo reference="chassis_link">
    <material>Gazebo/White</material>
  </gazebo>
  <!-- LEFT WHEEL LINK -->
  <joint name="left_wheel_joint" type="continuous">
    <parent link="base_link"/>
    <child link="left_wheel_link"/>
    <origin rpy="-1.5707963267948966 0 0" xyz="0 0.175 0"/>
    <axis xyz="0 0 1"/>
  </joint>
  <link name="left_wheel_link">
    <visual>
      <geometry>
        <cylinder length="0.04" radius="0.05"/>
      </geometry>
      <material name="blue"/>
    </visual>
    <collision>
      <geometry>
        <sphere radius="0.05"/>
      </geometry>
    </collision>
    <inertial>
      <origin rpy="0 0 0" xyz="0 0 0"/>
      <mass value="0.1"/>
      <inertia ixx="0.007583333333333333" ixy="0.0" ixz="0.0" iyy="0.007583333333333333" iyz="0.0" izz="0.0125"/>
    </inertial>
  </link>
  <gazebo reference="left_wheel_link">
    <material>Gazebo/Blue</material>
  </gazebo>
  <!-- RIGHT WHEEL LINK -->
  <joint name="right_wheel_joint" type="continuous">
    <parent link="base_link"/>
    <child link="right_wheel_link"/>
    <origin rpy="-1.5707963267948966 0 0" xyz="0 -0.175 0"/>
    <axis xyz="0 0 1"/>
  </joint>
  <link name="right_wheel_link">
    <visual>
      <geometry>
        <cylinder length="0.04" radius="0.05"/>
      </geometry>
      <material name="blue"/>
    </visual>
    <collision>
      <geometry>
        <sphere radius="0.05"/>
      </geometry>
    </collision>
    <inertial>
      <origin rpy="0 0 0" xyz="0 0 0"/>
      <mass value="0.1"/>
      <inertia ixx="0.007583333333333333" ixy="0.0" ixz="0.0" iyy="0.007583333333333333" iyz="0.0" izz="0.0125"/>
    </inertial>
  </link>
  <gazebo reference="right_wheel_link">
    <material>Gazebo/Blue</material>
  </gazebo>
  <!-- CASTER WHEEL LINK -->
  <joint name="caster_wheel_joint" type="fixed">
    <parent link="chassis_link"/>
    <child link="caster_wheel_link"/>
    <origin xyz="0.24 0 0"/>
  </joint>
  <link name="caster_wheel_link">
    <visual>
      <geometry>
        <sphere radius="0.05"/>
      </geometry>
      <material name="black"/>
    </visual>
    <collision>
      <geometry>
        <sphere radius="0.05"/>
      </geometry>
    </collision>
    <inertial>
      <origin rpy="0 0 0" xyz="0 0 0"/>
      <mass value="0.1"/>
      <inertia ixx="0.00010000000000000005" ixy="0.0" ixz="0.0" iyy="0.00010000000000000005" iyz="0.0" izz="0.00010000000000000005"/>
    </inertial>
  </link>
  <gazebo reference="caster_wheel_link">
    <material>Gazebo/Black</material>
    <mu1 value="0.001"/>
    <mu2 value="0.001"/>
  </gazebo>
  <!-- VLP-16 LiDAR -->
  <joint name="velodyne_base_mount_joint" type="fixed">
    <origin rpy="0 0 0" xyz="0.1 0 0.175"/>
    <parent link="chassis_link"/>
    <child link="velodyne_base_link"/>
  </joint>
  <link name="velodyne_base_link">
    <inertial>
      <mass value="0.83"/>
      <origin xyz="0 0 0.03585"/>
      <inertia ixx="0.000908059425" ixy="0" ixz="0" iyy="0.000908059425" iyz="0" izz="0.0011049624"/>
    </inertial>
    <visual>
      <geometry>
        <mesh filename="package://velodyne_description/meshes/VLP16_base_1.dae"/>
      </geometry>
    </visual>
    <visual>
      <geometry>
        <mesh filename="package://velodyne_description/meshes/VLP16_base_2.dae"/>
      </geometry>
    </visual>
    <collision>
      <origin rpy="0 0 0" xyz="0 0 0.03585"/>
      <geometry>
        <cylinder length="0.0717" radius="0.0516"/>
      </geometry>
    </collision>
  </link>
  <joint name="velodyne_base_scan_joint" type="fixed">
    <origin rpy="0 0 0" xyz="0 0 0.0377"/>
    <parent link="velodyne_base_link"/>
    <child link="velodyne"/>
  </joint>
  <link name="velodyne">
    <inertial>
      <mass value="0.01"/>
      <origin xyz="0 0 0"/>
      <inertia ixx="1e-7" ixy="0" ixz="0" iyy="1e-7" iyz="0" izz="1e-7"/>
    </inertial>
    <visual>
      <origin xyz="0 0 -0.0377"/>
      <geometry>
        <mesh filename="package://velodyne_description/meshes/VLP16_scan.dae"/>
      </geometry>
    </visual>
    <collision>
      <geometry>
        <sphere radius="0"/>
      </geometry>
    </collision>
  </link>
  <!-- Gazebo requires the velodyne_gazebo_plugins package -->
  <gazebo reference="velodyne">
    <sensor name="velodyne-VLP16" type="ray">
      <pose>0 0 0 0 0 0</pose>
      <visualize>false</visualize>
      <update_rate>10</update_rate>
      <ray>
        <scan>
          <horizontal>
            <samples>440</samples>
            <resolution>1</resolution>
            <min_angle>-3.141592653589793</min_angle>
            <max_angle>3.141592653589793</max_angle>
          </horizontal>
          <vertical>
            <samples>16</samples>
            <resolution>1</resolution>
            <min_angle>-0.2617993877991494</min_angle>
            <max_angle> 0.2617993877991494</max_angle>
          </vertical>
        </scan>
        <range>
          <min>0.3</min>
          <max>131.0</max>
          <resolution>0.001</resolution>
        </range>
        <noise>
          <type>gaussian</type>
          <mean>0.0</mean>
          <stddev>0.0</stddev>
        </noise>
      </ray>
      <plugin filename="libgazebo_ros_velodyne_laser.so" name="gazebo_ros_laser_controller">
        <ros>
          <namespace>/velodyne</namespace>
          <remapping>~/out:=/velodyne_points</remapping>
        </ros>
        <tf_prefix></tf_prefix>
        <frame_name>velodyne</frame_name>
        <organize_cloud>False</organize_cloud>
        <min_range>0.9</min_range>
        <max_range>130.0</max_range>
        <gaussian_noise>0.008</gaussian_noise>
      </plugin>
    </sensor>
  </gazebo>
  <!-- RIGHT CAMERA -->
  <joint name="right_camera_joint" type="fixed">
    <parent link="chassis_link"/>
    <child link="right_camera_link"/>
    <origin rpy="0 0 0" xyz="0.305 -0.12 0.08"/>
  </joint>
  <link name="right_camera_link">
    <visual>
      <geometry>
        <box size="0.010 0.03 0.03"/>
      </geometry>
      <material name="red"/>
    </visual>
  </link>
  <joint name="right_camera_optical_joint" type="fixed">
    <parent link="right_camera_link"/>
    <child link="right_camera_link_optical"/>
    <origin rpy="-1.5707963267948966 0 -1.5707963267948966" xyz="0 0 0"/>
  </joint>
  <link name="right_camera_link_optical"/>
  <gazebo reference="right_camera_link">
    <material>Gazebo/Red</material>
    <sensor name="right_camera" type="camera">
      <pose> 0 0 0 0 0 0 </pose>
      <visualize>false</visualize>
      <update_rate>10</update_rate>
      <camera>
        <horizontal_fov>1.089</horizontal_fov>
        <image>
          <format>R8G8B8</format>
          <width>640</width>
          <height>480</height>
        </image>
        <clip>
          <near>0.05</near>
          <far>8.0</far>
        </clip>
      </camera>
      <plugin filename="libgazebo_ros_camera.so" name="right_camera_controller">
        <frame_name>right_camera_link_optical</frame_name>
      </plugin>
    </sensor>
  </gazebo>
  <!-- LEFT CAMERA -->
  <joint name="left_camera_joint" type="fixed">
    <parent link="chassis_link"/>
    <child link="left_camera_link"/>
    <origin rpy="0 0 0" xyz="0.305 0.12 0.08"/>
  </joint>
  <link name="left_camera_link">
    <visual>
      <geometry>
        <box size="0.010 0.03 0.03"/>
      </geometry>
      <material name="green"/>
    </visual>
  </link>
  <joint name="left_camera_optical_joint" type="fixed">
    <parent link="left_camera_link"/>
    <child link="left_camera_link_optical"/>
    <origin rpy="-1.5707963267948966 0 -1.5707963267948966" xyz="0 0 0"/>
  </joint>
  <link name="left_camera_link_optical"/>
  <gazebo reference="left_camera_link">
    <material>Gazebo/Green</material>
    <sensor name="left_camera" type="camera">
      <pose> 0 0 0 0 0 0 </pose>
      <visualize>false</visualize>
      <update_rate>10</update_rate>
      <camera>
        <horizontal_fov>1.089</horizontal_fov>
        <image>
          <format>R8G8B8</format>
          <width>640</width>
          <height>480</height>
        </image>
        <clip>
          <near>0.05</near>
          <far>8.0</far>
        </clip>
      </camera>
      <plugin filename="libgazebo_ros_camera.so" name="left_camera_controller">
        <frame_name>left_camera_link_optical</frame_name>
      </plugin>
    </sensor>
  </gazebo>
  <!-- CONTROL -->
  <ros2_control name="GazeboSystem" type="system">
    <hardware>
      <plugin>gazebo_ros2_control/GazeboSystem</plugin>
    </hardware>
    <joint name="left_wheel_joint">
      <command_interface name="velocity">
        <param name="min">-10</param>
        <param name="max">10</param>
      </command_interface>
      <state_interface name="velocity"/>
      <state_interface name="position"/>
    </joint>
    <joint name="right_wheel_joint">
      <command_interface name="velocity">
        <param name="min">-10</param>
        <param name="max">10</param>
      </command_interface>
      <state_interface name="velocity"/>
      <state_interface name="position"/>
    </joint>
  </ros2_control>
  <gazebo>
    <plugin filename="libgazebo_ros2_control.so" name="gazebo_ros2_control">
      <parameters>/home/dev/test_ws/install/igvc_test/share/igvc_test/config/my_controllers.yaml</parameters>
    </plugin>
  </gazebo>
</robot>
